{"uuid": "c702b841-7a8e-49f8-bc86-4bc8a58d9d29", "children": ["3e9bfbfe-db04-4f12-bb22-e2a27354860e", "3befd03c-c0ac-44f9-a3ce-cf1d986a53e4", "9fb09600-dcf8-413b-bad5-134367029be7", "3d6ec886-387f-447c-af81-49a87d77553b"], "befores": [{"name": "init_web", "status": "broken", "statusDetails": {"message": "urllib3.exceptions.MaxRetryError: HTTPConnectionPool(host='127.0.0.1', port=4444): Max retries exceeded with url: /wd/hub/session (Caused by NewConnectionError('<urllib3.connection.HTTPConnection object at 0x0000028DDCE16488>: Failed to establish a new connection: [WinError 10061] 由于目标计算机积极拒绝，无法连接。'))\n", "trace": "  File \"D:\\python37\\lib\\site-packages\\pluggy\\callers.py\", line 187, in _multicall\n    res = hook_impl.function(*args)\n  File \"D:\\python37\\lib\\site-packages\\_pytest\\fixtures.py\", line 927, in pytest_fixture_setup\n    result = call_fixture_func(fixturefunc, request, kwargs)\n  File \"D:\\python37\\lib\\site-packages\\_pytest\\fixtures.py\", line 774, in call_fixture_func\n    res = next(it)\n  File \"e:\\day3\\conftest.py\", line 9, in init_web\n    driver = webdriver.Remote(command_executor='http://127.0.0.1:4444/wd/hub', desired_capabilities={'browserName': 'chrome'})\n  File \"D:\\python37\\lib\\site-packages\\selenium\\webdriver\\remote\\webdriver.py\", line 157, in __init__\n    self.start_session(capabilities, browser_profile)\n  File \"D:\\python37\\lib\\site-packages\\selenium\\webdriver\\remote\\webdriver.py\", line 252, in start_session\n    response = self.execute(Command.NEW_SESSION, parameters)\n  File \"D:\\python37\\lib\\site-packages\\selenium\\webdriver\\remote\\webdriver.py\", line 319, in execute\n    response = self.command_executor.execute(driver_command, params)\n  File \"D:\\python37\\lib\\site-packages\\selenium\\webdriver\\remote\\remote_connection.py\", line 374, in execute\n    return self._request(command_info[0], url, body=data)\n  File \"D:\\python37\\lib\\site-packages\\selenium\\webdriver\\remote\\remote_connection.py\", line 402, in _request\n    resp = http.request(method, url, body=body, headers=headers)\n  File \"D:\\python37\\lib\\site-packages\\urllib3\\request.py\", line 72, in request\n    **urlopen_kw)\n  File \"D:\\python37\\lib\\site-packages\\urllib3\\request.py\", line 150, in request_encode_body\n    return self.urlopen(method, url, **extra_kw)\n  File \"D:\\python37\\lib\\site-packages\\urllib3\\poolmanager.py\", line 326, in urlopen\n    response = conn.urlopen(method, u.request_uri, **kw)\n  File \"D:\\python37\\lib\\site-packages\\urllib3\\connectionpool.py\", line 670, in urlopen\n    **response_kw)\n  File \"D:\\python37\\lib\\site-packages\\urllib3\\connectionpool.py\", line 670, in urlopen\n    **response_kw)\n  File \"D:\\python37\\lib\\site-packages\\urllib3\\connectionpool.py\", line 670, in urlopen\n    **response_kw)\n  File \"D:\\python37\\lib\\site-packages\\urllib3\\connectionpool.py\", line 641, in urlopen\n    _stacktrace=sys.exc_info()[2])\n  File \"D:\\python37\\lib\\site-packages\\urllib3\\util\\retry.py\", line 399, in increment\n    raise MaxRetryError(_pool, url, error or ResponseError(cause))\n"}, "start": 1570275522536, "stop": 1570275527575}], "start": 1570275522536, "stop": 1570275528557}